Workbook

Sheet Anual
A1: Column1 | B1: Column2 | C1: Column3 | D1: Column4
A2: Mes | B2: Bruto | C2: Gastos | D2: Neto
A3: Janeiro | B3: 17355 | C3: 2739 | D3: 11076
A4: Fevereiro | B4: 11062 | C4: 481 | D4: 10017
A5: Março | B5: 12880 | C5: 2502 | D5: 8502
A6: Abril | B6: 9789 | C6: 2080 | D6: 6420
A7: Maio | B7: 7534 | C7: 1699 | D7: 5834
A8: Junho | B8: 6134 | C8: 1606 | D8: 4527
A9: Julho | B9: 7999 | C9: 1157 | D9: 6741
A10: Agosto | B10: 9739 | C10: 2085 | D10: 7653
A11: Setembro | B11: 14812 | C11: 2205 | D11: 12606
A12: Outubro | B12: 12550 | C12: 2765 | D12: 9253
A13: Novembro | B13: 15440 | C13: 2430 | D13: 13009
A14: Dezembro | B14: 27345 | C14: 3600 | D14: 23747
A15: Total | B15: =SUM(B3:B14) -> 152639 | C15: =SUM(C3:C14) -> 25349 | D15: =SUM(D3:D14) -> 119385
A16: Media/mes | B16: =AVERAGE(B3:B14) -> 12719.917 | C16: =AVERAGE(C3:C14) -> 2112.4167 | D16: =AVERAGE(D3:D14) -> 9948.75
C18: 2024
A19: Mes | B19: Bruto | C19: Gastos | D19: Neto
A20: Janeiro | B20: 21209 | C20: 4953 | D20: 16255
A21: Fevereiro | B21: 16157 | C21: 3682 | D21: 12474
A22: Março | B22: 18447 | C22: 3975 | D22: 14471
A23: Abril | B23: 13158 | C23: 4140 | D23: 9017
A24: Maio | B24: 12916 | C24: 3604 | D24: 9311
A25: Junho | B25: 14523 | C25: 3496 | D25: 11026
A26: Julho | B26: 11864 | C26: 4228 | D26: 7635
A27: Agosto | B27: 16129 | C27: 3694 | D27: 12434
A28: Setembro | B28: 16543 | C28: 4713 | D28: 11830
A29: Outubro | B29: 17700 | C29: 4548 | D29: 13152
A30: Novembro | B30: 18653 | C30: 4773 | D30: 13880
A31: Dezembro | B31: 23439 | C31: 4535 | D31: 18905
A32: Total | B32: =SUM(B20:B31) -> 200738 | C32: =SUM(C20:C31) -> 50341 | D32: =SUM(D20:D31) -> 150390
A33: Media/mes | B33: =AVERAGE(B20:B31) -> 16728.167 | C33: =AVERAGE(C20:C31) -> 4195.0833 | D33: =AVERAGE(D20:D31) -> 12532.5
C34: 2025
A35: Mes | B35: Bruto | C35: Gastos | D35: Neto
A36: Janeiro | B36: 20951 | C36: 5564 | D36: 15387
A37: Fevereiro | B37: 16410 | C37: 4996 | D37: 11414
A38: Março | B38: 15672 | C38: 3690 | D38: 11982
A39: Abril | B39: 12463 | C39: 4547 | D39: 7916
A40: Maio | B40: 14640 | C40: 3972 | D40: 10668
A41: Junho | B41: 12459 | C41: 3314 | D41: 9145
...

Sheet Aug 26
D1: 46235
A3: Data | B3: Vendas | C3: Gastos | D3: Tipo gasto | E3: Dinheiro | F3: 212
A4: 46235 | B4: 864 | C4: 4524 | D4: Cartao Nu | E4: Pix | F4: 88
A5: 46236 | B5: 643 | C5: 2003 | D5: Cartão Sicredi | E5: Cartao | F5: 393
A6: 46237 | F6: =SUM(F3:F5)-50 -> 643
A7: 46238 | C7: 353 | D7: Luz
A8: 46239 | C8: 89 | D8: Das
A9: 46240 | C9: 107 | D9: Contab
A10: 46241 | C10: 20 | D10: Restaurante
A11: 46242
A12: 46243
A13: 46244
A14: 46245 | C14: 7000 | D14: Faltou mês anterior
A15: 46246
A16: 46247
A17: 46248
A18: 46249
A19: 46250
A20: 46251
A21: 46252
A22: 46253
A23: 46254
A24: 46255
A25: 46256
A26: 46257
... A34: 46265
A35: Media | B35: =AVERAGE(B4:B34) -> 753.5
A36: Total bruto | B36: =SUM(B4:B33) -> 1507 | C36: =SUM(C4:C35) -> 14096
A37: Total neto | B37: =B36-C36 -> -12589
A38: Saldo | B38: =B37-15900 -> -28489

Sheet Jul 26
D1: 46204
A3: Data | B3: Vendas | C3: Gastos | D3: Tipo gasto | E3: Dinheiro
A4: 46204 | B4: 625 | C4: 3200 | D4: Cartao | E4: Pix
A5: 46205 | B5: 130 | D5: Boleto | E5: Cartao
A6: 46206 | B6: 114 | F6: =SUM(F3:F5)-50 -> -50
A7: 46207 | B7: 1180 | C7: 339 | D7: Luz
A8: 46208 | B8: 0 | C8: 89 | D8: Das
A9: 46209 | B9: 0 | C9: 107 | D9: Contab
A10: 46210 | B10: 278 | C10: 88 | D10: Restaurante
A11: 46211 | B11: 711 | C11: 50 | D11: Eletrica
A12: 46212 | B12: 709
A13: 46213 | B13: 477
A14: 46214 | B14: 0 | C14: 3900 | D14: Faltou mês anterior
A15: 46215 | B15: 708
A16: 46216 | B16: 236
A17: 46217 | B17: 334
A18: 46218 | B18: 509
A19: 46219 | B19: 646
A20: 46220 | B20: 621
A21: 46221 | B21: 969
A22: 46222 | B22: 518
A23: 46223 | B23: 723
A24: 46224 | B24: 624
A25: 46225 | B25: 0
A26: 46226 | B26: 485
... A34: 46234 | B34: 574
A35: Media
A36: Total bruto | B36: =SUM(B4:B33) -> 15118 | C36: =SUM(C4:C35) -> 7773
A37: Total neto | B37: =B36-C36+1617 -> 8962
A38: Saldo | B38: =B37-16000 -> -7038

Sheet Jun 26
D1: 46174
A3: Data | B3: Vendas | C3: Gastos | D3: Tipo gasto | E3: Dinheiro
A4: 46174 | B4: 332 | C4: 4272 | D4: Cartao | E4: Pix
A5: 46175 | B5: 418 | D5: Boleto | E5: Cartao
A6: 46176 | B6: 200 | F6: =SUM(F3:F5)-50 -> -50
A7: 46177 | B7: 1007 | C7: 368 | D7: Luz
A8: 46178 | B8: 583 | C8: 89 | D8: Das
A9: 46179 | B9: 774 | C9: 107 | D9: Contab
A10: 46180 | B10: 836 | C10: 165 | D10: Restaurante
A11: 46181 | B11: 526 | C11: 150 | D11: Eletrica
A12: 46182 | B12: 459
A13: 46183 | B13: 0
A14: 46184 | B14: 0 | C14: 4350 | D14: Faltou mês anterior
A15: 46185 | B15: 318
A16: 46186 | B16: 785
A17: 46187 | B17: 277
A18: 46188 | B18: 354
A19: 46189 | B19: 153
A20: 46190 | B20: 245
A21: 46191 | B21: 160
A22: 46192 | B22: 0
A23: 46193 | B23: 670
A24: 46194 | B24: 295
A25: 46195 | B25: 0
A26: 46196 | B26: 194
... A33: 46203 | B33: 138
A35: Media | B35: =AVERAGE(B4:B34) -> 364.53333
A36: Total bruto | B36: =SUM(B4:B33) -> 10936 | C36: =SUM(C4:C35) -> 9501
A37: Total neto | B37: =B36-C36 -> 1435
A38: Saldo | B38: =B37-15600+3174+7100 -> -3891

Sheet May 26
D1: 46143
A3: Data | B3: Vendas | C3: Gastos | D3: Tipo gasto | E3: Dinheiro
A4: 46143 | B4: 859 | C4: 3744 | D4: Cartao | E4: Pix
A5: 46144 | B5: 116 | D5: Boleto | E5: Cartao
A6: 46145 | B6: 521 | F6: =SUM(F3:F5) -> 0
A7: 46146 | B7: 469 | C7: 250 | D7: Luz
A8: 46147 | B8: 344 | C8: 89 | D8: Das
A9: 46148 | B9: 292 | C9: 107 | D9: Contab
A10: 46149 | B10: 648 | C10: 201 | D10: Restaurante
A11: 46150 | B11: 0
A12: 46151 | B12: 1270
A13: 46152 | B13: 298
A14: 46153 | B14: 462 | D14: Faltou mês anterior
A15: 46154 | B15: 449
A16: 46155 | B16: 391
A17: 46156 | B17: 248
A18: 46157 | B18: 166
A19: 46158 | B19: 719
A20: 46159 | B20: 0
A21: 46160 | B21: 239
A22: 46161 | B22: 235
A23: 46162 | B23: 221
A24: 46163 | B24: 296
A25: 46164 | B25: 0
A26: 46165 | B26: 702
... A34: 46173 | B34: 625
A35: Media | B35: =AVERAGE(B4:B34) -> 413.77419
A36: Total bruto | B36: =SUM(B4:B33) -> 12202 | C36: =SUM(C4:C35) -> 4391
A37: Total neto | B37: =B36-C36 -> 7811

Sheet April 26
D1: 46113
A3: Data | B3: Vendas | C3: Gastos | D3: Tipo gasto | E3: Dinheiro
A4: 46113 | B4: 500 | C4: 4125 | D4: Cartao | E4: Pix
A5: 46114 | B5: 700 | C5: 296 | D5: Boleto | E5: Cartao
A6: 46115 | B6: 1330 | F6: =SUM(F3:F5)-50 -> -50
A7: 46116 | B7: 1671 | C7: 748 | D7: Luz
A8: 46117 | B8: 0 | C8: 89 | D8: Das
A9: 46118 | B9: 625 | C9: 100 | D9: Contab
A10: 46119 | B10: 334 | C10: 233 | D10: Restaurante
A11: 46120 | B11: 454 | D11: Mercado
A12: 46121 | B12: 373 | C12: 50 | D12: Eletrica
A13: 46122 | B13: 615
A14: 46123 | B14: 1265 | D14: Faltou mês anterior
A15: 46124 | B15: 0
A16: 46125 | B16: 720
A17: 46126 | B17: 437
A18: 46127 | B18: 227
A19: 46128 | B19: 331
A20: 46129 | B20: 526
A21: 46130 | B21: 1071
A22: 46131 | B22: 767
A23: 46132 | B23: 886
A24: 46133 | B24: 550
A25: 46134 | B25: 415
A26: 46135 | B26: 395
... A33: 46142 | B33: 516
A34: Media | B34: =AVERAGE(B4:B33) -> 498.8
A35: Total bruto | B35: =SUM(B4:B33) -> 14964 | C35: =SUM(C4:C34) -> 5641
A36: Total neto | B36: =B35-C35-B65 -> 9323

Sheet March 26
D1: 46082
B2: Vendas | C2: Gastos
A3: 1 | B3: 844 | C3: 5176 | D3: Cartao | E3: Dinheiro
A4: 2 | B4: 321 | E4: Pix
A5: 3 | B5: 414 | E5: Cartao
A6: 4 | B6: 486 | C6: 616 | D6: Luz | F6: =SUM(F3:F5) -> 0
A7: 5 | B7: 336 | C7: 85 | D7: Das
A8: 6 | B8: 765 | C8: 100 | D8: Contab
A9: 7 | B9: 1709 | C9: 57 | D9: Restaurante
A10: 8 | B10: 264 | D10: Mercado
A11: 9 | B11: 659
A12: 10 | B12: 756
A13: 11 | B13: 264 | D13: Faltou
A14: 12 | B14: 522
A15: 13 | B15: 303
A16: 14 | B16: 1442
A17: 15 | B17: 623
A18: 16 | B18: 345
A19: 17 | B19: 255
A20: 18 | B20: 364
A21: 19 | B21: 394
A22: 20 | B22: 644
A23: 21 | B23: 794
A24: 22 | B24: 363
A25: 23 | B25: 373
... A33: 31 | B33: 19
A34: Total | B34: =SUM(B3:B33) -> 18058 | C34: =SUM(C3:C33) -> 6034
A35: Total neto | B35: =B34-C34-B64+F6 -> 12024
A36: Saldo | B36: =B35-17100 -> -5076

Sheet February 26
D1: 46054
B2: Vendas | C2: Gastos
A3: 1 | B3: 0 | C3: 4871 | D3: Cartao | E3: Dinheiro
A4: 2 | B4: 980 | C4: 476 | D4: Cartão | E4: Pix
A5: 3 | B5: 0 | E5: Cartao
A6: 4 | B6: 1081 | C6: 730 | D6: Luz | F6: =SUM(F3:F5) -> 0
A7: 5 | B7: 889 | C7: 85 | D7: Das
A8: 6 | B8: 887 | C8: 100 | D8: Contab
A9: 7 | B9: 1344 | C9: 78 | D9: Restaurante
A10: 8 | B10: 1319 | D10: Mercado
A11: 9 | B11: 845
A12: 10 | B12: 474
A13: 11 | B13: 808
A14: 12 | B14: 655
A15: 13 | B15: 481
A16: 14 | B16: 1227
A17: 15 | B17: 972
A18: 16 | B18: 944
A19: 17 | B19: 982
A20: 18 | B20: 653
A21: 19 | B21: 608
A22: 20 | B22: 451
... A30: 28 | B30: 1506
A34: Total | B34: =SUM(B3:B33) -> 21399 | C34: =SUM(C3:C33) -> 6340
A35: Total neto | B35: =B34-C34-B64+F6 -> 15059
A36: Saldo | B36: =B35-17200 -> -2141

Sheet January 26
D1: 46023 | F1: 2 pin -35
B2: Vendas | C2: Gastos
A3: 1 | B3: 0 | C3: 5787 | D3: Cartao | E3: Dinheiro
A4: 2 | B4: 0 | E4: Pix
A5: 3 | B5: 928 | C5: 403 | D5: Boleto | E5: Cartao
A6: 4 | B6: 802 | C6: 654 | D6: Luz | F6: =SUM(F3:F5) -> 0
A7: 5 | B7: 957 | C7: 83 | D7: Das
A8: 6 | B8: 885 | C8: 100 | D8: Contab
A9: 7 | B9: 1079 | C9: 482 | D9: Restaurante
A10: 8 | B10: 1424 | C10: 466 | D10: Mercado
A11: 9 | B11: 1025 | C11: 225 | D11: Leite
A12: 10 | B12: 0 | C12: 45 | D12: Bancos
A13: 11 | B13: 1054 | C13: 130 | D13: Maq chur
A14: 12 | B14: 1169 | C14: 50 | D14: Farol
A15: 13 | B15: 1126
A16: 14 | B16: 1017
A17: 15 | B17: 844
A18: 16 | B18: 994
A19: 17 | B19: 997
A20: 18 | B20: 981
A21: 19 | B21: 862
A22: 20 | B22: 846
A23: 21 | B23: 831
A24: 22 | B24: 674
A25: 23 | B25: 423
A26: 24 | B26: 1467
... A33: 31 | B33: 1497
A34: Total | B34: =SUM(B3:B33) -> 26530 | C34: =SUM(C3:C33) -> 8425
A35: Total neto | B35: =B34-C34+F6 -> 18105
A36: Saldo | B36: =B35-17055 -> 1050

Sheet Dezembro 25
D1: 45992
B2: Vendas | C2: Gastos
A3: 1 | B3: 491 | C3: 6257 | D3: Cartao | E3: Dinheiro
A4: 2 | B4: 554 | C4: 476 | D4: Cartao | E4: Pix
A5: 3 | B5: 700 | D5: Cartao | E5: Cartao
A6: 4 | B6: 809 | C6: 522 | D6: Luz | F6: =SUM(F3:F5) -> 0
A7: 5 | B7: 992 | C7: 82 | D7: Das
A8: 6 | B8: 2487 | C8: 100 | D8: Contab
A9: 7 | B9: 922 | C9: 198
A10: 8 | B10: 0
A11: 9 | B11: 519
A12: 10 | B12: 743
A13: 11 | B13: 801
A14: 12 | B14: 0
A15: 13 | B15: 1538
A16: 14 | B16: 751
A17: 15 | B17: 663
A18: 16 | B18: 650
A19: 17 | B19: 695
A20: 18 | B20: 733
A21: 19 | B21: 1109
... A33: 31 | B33: 640
A34: Total | B34: =SUM(B3:B33) -> 28409 | C34: =SUM(C3:C33) -> 7635
A35: Total neto | B35: =B34-C34-B64+F6 -> 20774
A36: Saldo | B36: =B35-15200-500 -> 5074

Sheet Novembro 25
D1: 45962
B2: Vendas | C2: Gastos
A3: 1 | B3: 344 | C3: 4390 | D3: Cartao | E3: Dinheiro
A4: 2 | B4: 885 | C4: 563 | D4: Cartao | E4: Pix
A5: 3 | B5: 557 | D5: Cartao | E5: Cartao
A6: 4 | B6: 549 | C6: 472 | D6: Luz | F6: =SUM(F3:F5) -> 0
A7: 5 | B7: 422 | C7: 82 | D7: Das
A8: 6 | B8: 775 | C8: 100 | D8: Contab
A9: 7 | B9: 824
A10: 8 | B10: 1338 | C10: 1600
A11: 9 | B11: 759
A12: 10 | B12: 850
A13: 11 | B13: 714 | C13: 228
A14: 12 | B14: 0
A15: 13 | B15: 263 | C15: 171
A16: 14 | B16: 1091
A17: 15 | B17: 1010
A18: 16 | B18: 1046
A19: 17 | B19: 269
A20: 18 | B20: 301
A21: 19 | B21: 651
A22: 20 | B22: 1041
A23: 21 | B23: 1125
A24: 22 | B24: 1236
A25: 23 | B25: 732
A26: 24 | B26: 604
A27: 25 | B27: 787
... A32: 30 | B32: 1565
A34: Total | B34: =SUM(B3:B33) -> 24005 | C34: =SUM(C3:C33) -> 7606
A35: Total neto | B35: =B34-C34-B64+F6 -> 16399

Sheet Outubro 25
D1: 45931
B2: Vendas | C2: Gastos
A3: 1 | B3: 296 | C3: 3636 | D3: Cartao | E3: Dinheiro
A4: 2 | B4: 269 | C4: 813 | D4: Cartao | E4: Pix
A5: 3 | B5: 349 | C5: 478 | D5: Cartao | E5: Cartao
A6: 4 | B6: 1454 | C6: 493 | D6: Luz | F6: =SUM(F3:F5) -> 0
A7: 5 | B7: 1254 | C7: 82 | D7: Das
A8: 6 | B8: 306 | C8: 100 | D8: Contab
A9: 7 | B9: 253
A10: 8 | B10: 341
A11: 9 | B11: 285
A12: 10 | B12: 974
A13: 11 | B13: 1500
A14: 12 | B14: 0
A15: 13 | B15: 470
A16: 14 | B16: 655
A17: 15 | B17: 643
A18: 16 | B18: 134
A19: 17 | B19: 121
A20: 18 | B20: 820
... A33: 31 | B33: 677
A34: Total | B34: =SUM(B3:B33) -> 15958 | C34: =SUM(C3:C33) -> 5602
A35: Total neto | B35: =B34-C34-B64+F6 -> 10356
A36: Saldo

Sheet Setembro 25
D1: 45901
B2: Vendas | C2: Gastos
A3: 1 | B3: 347 | C3: 4290 | D3: Cartao | E3: Dinheiro
A4: 2 | B4: 573 | C4: 813 | E4: Pix
A5: 3 | B5: 560 | C5: 100 | D5: Contab | E5: Cartao
A6: 4 | B6: 178 | C6: 397 | D6: Luz | F6: =SUM(F3:F5) -> 0
A7: 5 | B7: 100 | C7: 82 | D7: Das
A8: 6 | B8: 855 | C8: 245
A9: 7 | B9: 696 | C9: 150 | D9: Kouth
A10: 8 | B10: 975 | C10: 300
A11: 9 | B11: 474
A12: 10 | B12: 925 | C12: 110
A13: 11 | B13: 564
A14: 12 | B14: 757
A15: 13 | B15: 1457
A16: 14 | B16: 530
A17: 15 | B17: 362
A18: 16 | B18: 531
A19: 17 | B19: 504
A20: 18 | B20: 580
A21: 19 | B21: 532
A22: 20 | B22: 1020
A23: 21 | B23: 0
A24: 22 | B24: 485
... A32: 30 | B32: 0
A33: Evento | B33: 1806
A34: Total | B34: =SUM(B3:B33) -> 19431 | C34: =SUM(C3:C33) -> 6487
A35: Total neto | B35: =B34-C34+F6 -> 12944

Sheet Agosto 25
D1: 45870
B2: Vendas | C2: Gastos
A3: 1 | B3: 576 | C3: 4953 | D3: Cartao | E3: Dinheiro
A4: 2 | B4: 1154 | E4: Pix
A5: 3 | B5: 0 | C5: 100 | D5: Contab | E5: Cartao
A6: 4 | B6: 0 | C6: 440 | D6: Luz | F6: =SUM(F3:F5) -> 0
A7: 5 | B7: 347 | C7: 82 | D7: Das
A8: 6 | B8: 513
A9: 7 | B9: 636
A10: 8 | B10: 410
A11: 9 | B11: 1042
A12: 10 | B12: 0
A13: 11 | B13: 454
A14: 12 | B14: 455
A15: 13 | B15: 440
A16: 14 | B16: 413
A17: 15 | B17: 397
A18: 16 | B18: 1505
A19: 17 | B19: 790
... A33: 31 | B33: 473
A34: Total | B34: =SUM(B3:B33) -> 15906 | C34: =SUM(C3:C33) -> 5575
A35: Total neto | B35: =B34-C34-B64+F6 -> 10331
A36: Saldo | B36: =B35-15025+794 -> -3900

Sheet Julho 25
D1: 45839
B2: Vendas | C2: Gastos
A3: 1 | B3: 152 | C3: 4873.76 | D3: Cartao | E3: Dinheiro
A4: 2 | B4: 243 | C4: 95 | D4: Guia | E4: Pix
A5: 3 | B5: 543 | C5: 100 | D5: Contab | E5: Cartao
A6: 4 | B6: 544 | C6: 293 | D6: Luz | F6: =SUM('Agosto 25'!G3:G5) -> 0
A7: 5 | B7: 1147 | C7: 82 | D7: Das
A8: 6 | B8: 689
A9: 7 | B9: 911
A10: 8 | B10: 515
A11: 9 | B11: 546
A12: 10 | B12: 476
A13: 11 | B13: 455
A14: 12 | B14: 1046
A15: 13 | B15: 946
A16: 14 | B16: 830
A17: 15 | B17: 659
A18: 16 | B18: 610
A19: 17 | B19: 152
... A33: 31 | B33: 434
A34: Total | B34: =SUM(B3:B33) -> 17519 | C34: =SUM(C3:C33) -> 5443.76
A35: Total neto | B35: =B34-C34-B64+F6 -> 12075.24
A36: Saldo | B36: =B35-16500 -> -4424.76

Sheet Junho 25
D1: 45809
B2: Vendas | C2: Gastos
A3: 1 | B3: 747 | C3: 3675 | D3: Cartao | E3: Dinheiro
A4: 2 | B4: 293 | E4: Pix
A5: 3 | B5: 256 | C5: 100 | D5: Contab | E5: Cartao
A6: 4 | B6: 342 | C6: 414 | D6: Luz | F6: =SUM(F3:F5) -> 0
A7: 5 | B7: 0 | C7: 82 | D7: Das
A8: 6 | B8: 531 | C8: 43
A9: 7 | B9: 1237
A10: 8 | B10: 711
A11: 9 | B11: 600
A12: 10 | B12: 535
A13: 11 | B13: 372
A14: 12 | B14: 323
A15: 13 | B15: 572
A16: 14 | B16: 493
A17: 15 | B17: 393
A18: 16 | B18: 542
A19: 17 | B19: 341
A20: 18 | B20: 587
... A32: 30 | B32: 106
A34: Total | B34: =SUM(B3:B33) -> 12459 | C34: =SUM(C3:C33)-1000 -> 3314
A35: Total neto | B35: =B34-C34-B64+F6 -> 9145
A36: Saldo

Sheet Maio 25
D1: 45778
B2: Vendas | C2: Gastos
A3: 1 | B3: 0 | C3: 3184 | D3: Cartao | E3: Dinheiro
A4: 2 | B4: 806 | E4: Pix
A5: 3 | B5: 745 | C5: 100 | D5: Contab | E5: Cartao
A6: 4 | B6: 576 | C6: 606 | D6: Luz | F6: =SUM(F3:F5) -> 0
A7: 5 | B7: 609 | C7: 82 | D7: Das
A8: 6 | B8: 422
A9: 7 | B9: 602
A10: 8 | B10: 826
A11: 9 | B11: 260
A12: 10 | B12: 1215
A13: 11 | B13: 360
A14: 12 | B14: 506
A15: 13 | B15: 407
A16: 14 | B16: 337
A17: 15 | B17: 325
A18: 16 | B18: 339
A19: 17 | B19: 925
... A33: 31 | B33: 687
A34: Total | B34: =SUM(B3:B33) -> 14640 | C34: =SUM(C3:C33) -> 3972
A35: Total neto | B35: =B34-C34-B64+F6 -> 10668
A36: Saldo

Sheet Abril 25
D1: 45748
B2: Vendas | C2: Gastos
A3: 1 | B3: 333 | C3: 3876 | D3: Cartao | E3: Dinheiro
A4: 2 | B4: 436 | E4: Pix
A5: 3 | B5: 500 | C5: 100 | D5: Contab | E5: Cartao
A6: 4 | B6: 422 | C6: 489 | D6: Luz | F6: =SUM(F3:F5) -> 0
A7: 5 | B7: 825 | C7: 82 | D7: Das
A8: 6 | B8: 794
A9: 7 | B9: 541
A10: 8 | B10: 0
A11: 9 | B11: 639
A12: 10 | B12: 387
A13: 11 | B13: 390
A14: 12 | B14: 220
A15: 13 | B15: 0
A16: 14 | B16: 581
A17: 15 | B17: 275
A18: 16 | B18: 420
A19: 17 | B19: 648
... A32: 30 | B32: 275
A34: Total | B34: =SUM(B3:B33) -> 12463 | C34: =SUM(C3:C33) -> 4547
A35: Total neto | B35: =B34-C34-B64+F6 -> 7916
A36: Saldo

Sheet Mar 25
D1: 45717
B2: Vendas | C2: Gastos
C3: 2367 | D3: Cartao | E3: Dinheiro
A4: 2 | B4: 515 | C4: 476 | D4: Cartao | E4: Pix
A5: 3 | B5: 708 | C5: 100 | D5: Contab | E5: Cartao
A6: 4 | B6: 1166 | C6: 601 | D6: Luz | F6: =SUM(F3:F5) -> 0
A7: 5 | B7: 151 | C7: 82 | D7: Das
A8: 6 | B8: 482 | C8: 64
A9: 7 | B9: 860
A10: 8 | B10: 1642
A11: 9 | B11: 538
A12: 10 | B12: 780
A13: 11 | B13: 0
A14: 12 | B14: 494
A15: 13 | B15: 349
A16: 14 | B16: 682
A17: 15 | B17: 233
A18: 16 | B18: 824
A19: 17 | B19: 432
A20: 18 | B20: 381
... A33: 31 | B33: 395
A34: Total | B34: =SUM(B3:B33) -> 15672 | C34: =SUM(C3:C33) -> 3690
A35: Total neto | B35: =B34-C34-B64+F6 -> 11982
A36: Saldo

Sheet Fev 25
D2: 45689
B3: Vendas | C3: Gastos
A4: 1 | B4: 492 | C4: 4862 | D4: Cartao Nu | E4: Dinheiro
A5: 2 | B5: 0 | C5: 686 | D5: Luz | E5: Pix
A6: 3 | B6: 765 | C6: 290 | D6: Leite | E6: Cartao
A7: 4 | B7: 815 | C7: 100 | D7: Contab | F7: =SUM(F4:F6) -> 0
A8: 5 | B8: 519 | C8: 58 | D8: Papel crê
A9: 6 | B9: 707
A10: 7 | B10: 571
A11: 8 | B11: 1009
A12: 9 | B12: 190
A13: 10 | B13: 513
A14: 11 | B14: 765
A15: 12 | B15: 509
A16: 13 | B16: 500
A17: 14 | B17: 571
A18: 15 | B18: 802
A19: 16 | B19: 668
A20: 17 | B20: 429
... A32: 45717 | B32: 1074
A35: Total | B35: =SUM(B4:B34) -> 16410 | C35: =SUM(C4:C34)-1000 -> 4996
A36: Total neto | B36: =B35-C35-B65+F7 -> 11414
A37: Saldo

Sheet Jan 25
D2: 45658
B3: Vendas | C3: Gastos
A4: 1 | B4: 0 | C4: 5137 | D4: Cartao Nu | E4: Dinheiro
A5: 2 | B5: 0 | C5: 427 | D5: Luz | E5: Pix
A6: 3 | B6: 1015 | E6: Cartao
A7: 4 | B7: 711 | F7: =SUM(F4:F6) -> 0
A8: 5 | B8: 978
A9: 6 | B9: 908
A10: 7 | B10: 1105
A11: 8 | B11: 796
A12: 9 | B12: 805
A13: 10 | B13: 992
A14: 11 | B14: 1257
A15: 12 | B15: 609
A16: 13 | B16: 525
A17: 14 | B17: 751
A18: 15 | B18: 856
A19: 16 | B19: 1068
... A34: 31 | B34: 528
A35: Total | B35: =SUM(B4:B34) -> 20951 | C35: =SUM(C4:C34) -> 5564
A36: Total neto | B36: =B35-C35-B65+F7 -> 15387
A37: Saldo

Sheet Dez 24
D2: 45627
B3: Vendas | C3: Gastos
B4: 1107 | C4: 3944 | D4: Cartao Nu | E4: Dinheiro
A5: 2 | B5: 408 | C5: 411 | D5: Luz | E5: Pix
A6: 3 | B6: 385 | C6: 180 | D6: Coco | E6: Cartao
A7: 4 | B7: 400 | F7: =SUM(F4:F6) -> 0
A8: 5 | B8: 541
A9: 6 | B9: 630
A10: 7 | B10: 244
A11: 8 | B11: 0
A12: 9 | B12: 416
A13: 10 | B13: 786
A14: 11 | B14: 900
A15: 12 | B15: 705
A16: 13 | B16: 470
A17: 14 | B17: 1303
A18: 15 | B18: 1144
A19: 16 | B19: 1474
... A34: 31 | B34: 645
A35: Total | B35: =SUM(B4:B34) -> 24546 | C35: =SUM(C4:C34) -> 4535
A36: Total neto | B36: =B35-C35-B65+F7 -> 20011

Sheet Nov 24
D2: 45597
B3: Vendas | C3: Gastos
A4: 1 | B4: 548 | C4: 4472 | D4: Cartao Nu | E4: Dinheiro
A5: 2 | B5: 0 | C5: 239.46 | D5: Luz | E5: Pix
A6: 3 | B6: 651 | C6: 62 | E6: Cartao
A7: 4 | B7: 526 | F7: =SUM(F4:F6) -> 0
A8: 5 | B8: 340
A9: 6 | B9: 564
A10: 7 | B10: 0
A11: 8 | B11: 637
A12: 9 | B12: 1748
A13: 10 | B13: 612
A14: 11 | B14: 139
A15: 12 | B15: 354
A16: 13 | B16: 1131
A17: 14 | B17: 927
A18: 15 | B18: 660
A19: 16 | B19: 0
... A34: 45627 | B34: 1107
A35: Total | B35: =SUM(B4:B34) -> 18653 | C35: =SUM(C4:C34) -> 4773.46
A36: Total neto | B36: =B35-C35-B65+F7 -> 13879.54
A37: Faltam | B37: =14200-B36 -> 320.46

Sheet Outubro 24
D2: 45566
B3: Vendas | C3: Gastos
A4: 1 | B4: 577 | C4: 4250 | D4: Cartao Nu | E4: Dinheiro
A5: 2 | B5: 586 | C5: 207 | D5: Luz | E5: Pix
A6: 3 | B6: 319 | C6: 91 | E6: Cartao
A7: 4 | B7: 594 | F7: =SUM(F4:F6) -> 0
A8: 5 | B8: 1771
A9: 6 | B9: 583
A10: 7 | B10: 1291
A11: 8 | B11: 564
A12: 9 | B12: 0
A13: 10 | B13: 0
A14: 11 | B14: 0
A15: 12 | B15: 1472
A16: 13 | B16: 1420
A17: 14 | B17: 908
A18: 15 | B18: 470
A19: 16 | B19: 366
... A34: 31 | B34: 673
A35: Total | B35: =SUM(B4:B34) -> 17700 | C35: =SUM(C4:C34) -> 4548
A36: Total neto | B36: =B35-C35+F7 -> 13152

Sheet Setembro 24
D2: 45536
B3: Vendas | C3: Gastos
A4: 1 | B4: 0 | C4: 3747 | D4: Cartao Nu | E4: Dinheiro
A5: 2 | B5: 568 | C5: 466 | D5: Luz | E5: Pix
A6: 3 | B6: 624 | C6: 214 | D6: Cartao inter | E6: Cartao
A7: 4 | B7: 213 | C7: 106 | F7: =SUM(F4:F6)-26 -> -26
A8: 5 | B8: 277 | C8: 180
A9: 6 | B9: 685
A10: 7 | B10: 1891
A11: 8 | B11: 1056
A12: 9 | B12: 810
A13: 10 | B13: 642
A14: 11 | B14: 572
A15: 12 | B15: 513
A16: 13 | B16: 663
A17: 14 | B17: 346
A18: 15 | B18: 0
A19: 16 | B19: 182
A20: 17 | B20: 463
... A33: 30 | B33: 435
A35: Total | B35: =SUM(B4:B34) -> 16569 | C35: =SUM(C4:C34) -> 4713
A36: Total neto | B36: =B35-C35-B65+F7 -> 11830

Sheet Agosto 24
D2: 45505
B3: Vendas | C3: Gastos
A4: 1 | B4: 424 | C4: 3535.45 | D4: Cartao Nu | E4: Dinheiro
A5: 2 | B5: 488 | C5: 158.71 | D5: Luz | E5: Pix
A6: 3 | B6: 995 | E6: Cartao
A7: 4 | B7: 833 | F7: =SUM(F4:F6) -> 0
A8: 5 | B8: 469
A9: 6 | B9: 720
A10: 7 | B10: 149
A11: 8 | B11: 206
A12: 9 | B12: 362
A13: 10 | B13: 1009
A14: 11 | B14: 0
A15: 12 | B15: 219
A16: 13 | B16: 267
A17: 14 | B17: 236
A18: 15 | B18: 555
A19: 16 | B19: 657
... A34: 31 | B34: 994
A35: Total | B35: =SUM(B4:B34) -> 16129 | C35: =SUM(C4:C34) -> 3694.16
A36: Total neto | B36: =B35-C35-B65+F7 -> 12434.84
A37: Faltam | B37: =12800-B36 -> 365.16

Sheet Julho 24
D2: 45474
B3: Vendas | C3: Gastos
A4: 1 | B4: 370 | C4: 3911.96 | D4: Cartao Nu | E4: Dinheiro
A5: 2 | B5: 248 | C5: 316.18 | D5: Luz | E5: Pix
A6: 3 | B6: 524 | E6: Cartao
A7: 4 | B7: 430 | F7: =SUM(F4:F6) -> 0
A8: 5 | B8: 381
A9: 6 | B9: 1136
A10: 7 | B10: 0
A11: 8 | B11: 0
A12: 9 | B12: 0
A13: 10 | B13: 282
A14: 11 | B14: 0
A15: 12 | B15: 0
A16: 13 | B16: 0
A17: 14 | B17: 0
A18: 15 | B18: 287
A19: 16 | B19: 324
... A34: 31 | B34: 491
A35: Total | B35: =SUM(B4:B34) -> 11864 | C35: =SUM(C4:C34) -> 4228.14
A36: Total neto | B36: =B35-C35-B65+F7 -> 7635.86
A38: Faltam | B38: =12100-B36-2420-1314 -> 730.14

Sheet Junho 24
D2: 45444
B3: Vendas | C3: Gastos
A4: 1 | B4: 775 | C4: 3150 | D4: Cartao Nu | E4: Dinheiro
A5: 2 | B5: 693 | C5: 346.36 | D5: Luz | E5: Pix
A6: 3 | B6: 529 | E6: Cartao
A7: 4 | B7: 468 | F7: =SUM(F4:F6) -> 0
A8: 5 | B8: 401
A9: 6 | B9: 650
A10: 7 | B10: 636
A11: 8 | B11: 1115
A12: 9 | B12: 775
A13: 10 | B13: 864
A14: 11 | B14: 269
A15: 12 | B15: 536
A16: 13 | B16: 336
A17: 14 | B17: 410
A18: 15 | B18: 630
A19: 16 | B19: 136
... A33: 30 | B33: 0
A35: Total | B35: =SUM(B4:B34) -> 14523 | C35: =SUM(C4:C34) -> 3496.36
A36: Total neto | B36: =B35-C35-B65+F7 -> 11026.64
A42: Parte Irma | C42: Cássia
B65: =SUM(B43:B64) -> 0

Sheet Maio 24
D2: 45413
B3: Vendas | C3: Gastos
A4: 1 | B4: 0 | C4: 3187.01 | D4: Cartao Nu | E4: Dinheiro
A5: 2 | B5: 440 | C5: 88.14 | D5: Luz | E5: Pix
A6: 3 | B6: 0 | C6: 76.99 | D6: Luz | E6: Cartao
A7: 4 | B7: 1302 | C7: 252.39 | D7: Luz | F7: =SUM(F4:F6) -> 0
A8: 5 | B8: 840
A9: 6 | B9: 479
A10: 7 | B10: 545
A11: 8 | B11: 732
A12: 9 | B12: 377
A13: 10 | B13: 622
A14: 11 | B14: 1418
A15: 12 | B15: 623
A16: 13 | B16: 51
A17: 14 | B17: 378
A18: 15 | B18: 197
A19: 16 | B19: 479
... A34: 31 | B34: 512
A35: Total | B35: =SUM(B4:B34) -> 12916 | C35: =SUM(C4:C34) -> 3604.53
A36: Total neto | B36: =B35-C35-B65+F7 -> 9311.47
A42: Parte Irma | C42: Cássia
B65: =SUM(B43:B64) -> 0

Sheet Abril 24
D2: 45383
B3: Vendas | C3: Gastos
A4: 1 | B4: 0 | C4: 3871.21 | D4: Cartao Nu | E4: Dinheiro
A5: 2 | B5: 242 | C5: 92.94 | D5: Luz | E5: Pix
A6: 3 | B6: 367 | C6: 88.14 | D6: Luz | E6: Cartao
A7: 4 | B7: 587 | C7: 88.15 | D7: Agua | F7: =SUM(F4:F6) -> 0
A8: 5 | B8: 377
A9: 6 | B9: 1582
A10: 7 | B10: 0
A11: 8 | B11: 656
A12: 9 | B12: 446
A13: 10 | B13: 444
A14: 11 | B14: 446
A15: 12 | B15: 593
A16: 13 | B16: 916
A17: 14 | B17: 0
A18: 15 | B18: 409
A19: 16 | B19: 0
... A33: 30 | B33: 407
A35: Total | B35: =SUM(B4:B34) -> 13158 | C35: =SUM(C4:C34) -> 4140.44
A36: Total neto | B36: =B35-C35-B65+F7 -> 9017.56
A37: Neto real | B37: =B36-B38 -> 8617.56
A38: Dani | B38: 400
A42: Parte Irma | C42: Cássia
A49: Kucoin
A50: 270
B65: =SUM(B43:B64) -> 0

Sheet Março 24
D2: 45352
B3: Vendas | C3: Gastos
A4: 1 | B4: 692 | C4: 3754 | D4: Cartão Nu | E4: Dinheiro
A5: 2 | B5: 1094 | C5: 88.34 | D5: Luz | E5: Pix
A6: 3 | B6: 704 | C6: 29.09 | D6: Alvara | E6: Cartao
A7: 4 | B7: 394 | F7: =SUM(F4:F6) -> 0
A8: 5 | B8: 560 | C8: 104.03 | D8: Agua
A9: 6 | B9: 434
A10: 7 | B10: 537
A11: 8 | B11: 368
A12: 9 | B12: 1500
A13: 10 | B13: 1006
A14: 11 | B14: 648
A15: 12 | B15: 587
A16: 13 | B16: 592
A17: 14 | B17: 580
A18: 15 | B18: 348
A19: 16 | B19: 1107
A20: 17 | B20: 0
... A34: 31 | B34: 0
A35: Total | B35: =SUM(B4:B34) -> 18447 | C35: =SUM(C4:C34) -> 3975.46
A36: Total neto | B36: =B35-C35-B65+F7 -> 14471.54
A37: Vai guardar | B37: =B36-11300-200 -> 2971.54
A42: Parte Irma | C42: Cássia
B65: =SUM(B43:B64) -> 0

Sheet Fevereiro 24
D2: 45323
B3: Vendas | C3: Gastos
A4: 1 | B4: 577 | C4: 3246.46 | D4: Cartão Nu | E4: Dinheiro
A5: 2 | B5: 494 | C5: 88.34 | D5: Luz | E5: Pix
A6: 3 | B6: 1536 | C6: 43.6 | E6: Cartao
A7: 4 | B7: 939 | C7: 53.88 | F7: =SUM(F4:F6) -> 0
A8: 5 | B8: 247 | C8: 50
A9: 6 | B9: 167 | C9: 200
A10: 7 | B10: 540
A11: 8 | B11: 827
A12: 9 | B12: 750
A13: 10 | B13: 1467
A14: 11 | B14: 848
A15: 12 | B15: 639
A16: 13 | B16: 184
A17: 14 | B17: 318
A18: 15 | B18: 291
A19: 16 | B19: 687
A20: 17 | B20: 1163
A21: 18 | B21: 557
... A32: 29 | B32: 395
A35: Total | B35: =SUM(B4:B34) -> 16157 | C35: =SUM(C4:C34) -> 3682.28
A36: Total neto | B36: =B35-C35-B65+F7 -> 12474.72
A37: Vai guardar | B37: =B36-9600 -> 2874.72
A42: Parte Irma | C42: Cássia
B65: =SUM(B43:B64) -> 0

Sheet Janeiro 24 
D2: 45292
B3: Vendas | C3: Gastos
A4: 1 | B4: 0 | C4: 3496.99 | D4: Cartão Nu | E4: Dinheiro
A5: 2 | B5: 795 | C5: 74.74 | D5: Luz | E5: Pix
A6: 3 | B6: 603 | C6: 381 | D6: Ss | E6: Cartao
A7: 4 | B7: 906 | C7: 200 | D7: Laine | F7: =SUM(F4:F6) -> 0
A8: 5 | B8: 927 | C8: 301
A9: 6 | B9: 1373 | C9: 500
A10: 7 | B10: 906
A11: 8 | B11: 1062
A12: 9 | B12: 564
A13: 10 | B13: 933
A14: 11 | B14: 569
A15: 12 | B15: 489
A16: 13 | B16: 0
A17: 14 | B17: 683
A18: 15 | B18: 482
A19: 16 | B19: 773
A20: 17 | B20: 748
A21: 18 | B21: 887 | AK21: .
A22: 19 | B22: 662
A23: 20 | B23: 935
A24: 21 | B24: 602
A25: 22 | B25: 572
A26: 23 | B26: 551
A27: 24 | B27: 640
A28: 25 | B28: 515
A29: 26 | B29: 664
A30: 27 | B30: 909
A31: 28 | B31: 131
A32: 29 | B32: 850
A33: 30 | B33: 842
A34: 31 | B34: 636
A35: Total | B35: =SUM(B4:B34) -> 21209 | C35: =SUM(C4:C34) -> 4953.73
A36: Total neto | B36: =B35-C35-B65+F7 -> 16255.27
A42: Parte Irma | C42: Cássia
B65: =SUM(B43:B64) -> 0

Sheet Dezembro 23
D2: 45261
B3: Vendas | C3: Gastos
C4: 2614.79 | D4: Cartao Nu | E4: Dinheiro
A5: 2 | B5: 1375 | C5: 99.38 | D5: Luz | E5: Pix
A6: 3 | B6: 752 | C6: 87.97 | D6: Luz | E6: Cartao
A7: 4 | B7: 219 | C7: 21 | F7: =SUM(F4:F6) -> 0
A8: 5 | B8: 827
A9: 6 | B9: 837 | C9: 242.7 | D9: Stock
A10: 7 | B10: 0 | C10: 236.96 | D10: Stock
A11: 8 | B11: 978 | C11: 88.15 | D11: Agua
A12: 9 | B12: 1781 | C12: 75.81 | D12: Coco
A13: 10 | B13: 664 | C13: 119.7 | D13: Coco
A14: 11 | B14: 806 | C14: 11.2
A15: 12 | B15: 854
A16: 13 | B16: 850
A17: 14 | B17: 621
A18: 15 | B18: 1051
A19: 16 | B19: 2222
A20: 17 | B20: 1258
A21: 18 | B21: 926
A22: 19 | B22: 1289
A23: 20 | B23: 689
A24: 21 | B24: 1158
A25: 22 | B25: 1358
A26: 23 | B26: 1130
... A34: 31 | B34: 0
A35: Total | B35: =SUM(B4:B34) -> 26501 | C35: =SUM(C4:C34) -> 3597.66
A36: Total neto | B36: =B35-C35-B65+F7 -> 22903.34
A42: Parte Irma | C42: Cássia
B65: =SUM(B43:B64) -> 0

Sheet Novembro 23
D2: 45231
B3: Vendas | C3: Gastos
A4: 1 | B4: 366 | C4: 1422.26 | D4: Cartao Nu | E4: Dinheiro
A5: 2 | B5: 0 | C5: 806.85 | D5: Ss | E5: Pix
A6: 3 | B6: 0 | C6: 88.14 | D6: Luz | E6: Cartao
A7: 4 | B7: 631 | C7: 20 | F7: =SUM(F4:F6) -> 0
A8: 5 | B8: 613 | C8: 92.89 | D8: Agua
A9: 6 | B9: 641
A10: 7 | B10: 1002
A11: 8 | B11: 771
A12: 9 | B12: 0
A13: 10 | B13: 804
A14: 11 | B14: 1711
A15: 12 | B15: 0
A16: 13 | B16: 762
A17: 14 | B17: 0
A18: 15 | B18: 1021
A19: 16 | B19: 474
A20: 17 | B20: 651
... A34: 45261 | B34: 844
A35: Total | B35: =SUM(B4:B34) -> 16284 | C35: =SUM(C4:C34) -> 2430.14
A36: Total neto | B36: =B35-C35-B65+F7 -> 13853.86
A42: Parte Irma | C42: Cássia
B65: =SUM(B43:B64) -> 0

Sheet Outubro 23
D2: 45200
B3: Vendas | C3: Gastos
A4: 1 | B4: 664 | C4: 2326 | D4: Cartao Nu | E4: Dinheiro
A5: 2 | B5: 502 | C5: 351 | D5: Ss | E5: Pix
A6: 3 | B6: 452 | E6: Cartao
A7: 4 | B7: 294 | F7: =SUM(F4:F6) -> 0
A8: 5 | B8: 0
A9: 6 | B9: 910 | C9: 88.04 | D9: Luz
A10: 7 | B10: 1155
A11: 8 | B11: 0
A12: 9 | B12: 487
A13: 10 | B13: 629
A14: 11 | B14: 620
A15: 12 | B15: 546
A16: 13 | B16: 505
A17: 14 | B17: 766
A18: 15 | B18: 824
A19: 16 | B19: 710
A20: 17 | B20: 232
A21: 18 | B21: 371
... A34: 31 | B34: 0
A35: Total | B35: =SUM(B4:B34) -> 12550 | C35: =SUM(C4:C34) -> 2765.04
A36: Total neto | B36: =B35-C35-B65+F7 -> 9252.96
A42: Parte Irma | C42: Cássia
B43: 532 | C43: 266
B65: =SUM(B43:B64) -> 532

Sheet Setembro 23
D2: 45170
B3: Vendas | C3: Gastos
A4: 1 | B4: 394 | C4: 607.87 | D4: S.S. | E4: Dinheiro
A5: 2 | B5: 0 | C5: 1318.07 | D5: Cartão Nu | E5: Pix
A6: 3 | B6: 0 | C6: 90.56 | D6: Luz | E6: Cartao
A7: 4 | B7: 126 | C7: 32.62 | D7: Cartão Nu | F7: =SUM(F4:F6) -> 0
A8: 5 | B8: 372 | C8: 23
A9: 6 | B9: 409 | C9: 11.75
A10: 7 | B10: 808 | C10: 22
A11: 8 | B11: 0 | C11: 99.75
A12: 9 | B12: 362
A13: 10 | B13: 1038
A14: 11 | B14: 644
A15: 12 | B15: 394
A16: 13 | B16: 0
A17: 14 | B17: 68
A18: 15 | B18: 474
A19: 16 | B19: 984
A20: 17 | B20: 950
A21: 18 | B21: 596
A22: 19 | B22: 461
A23: 20 | B23: 311
... A33: 30 | B33: 998
A35: Total | B35: =SUM(B4:B34) -> 14812 | C35: =SUM(C4:C34) -> 2205.62
A36: Total neto | B36: =B35-C35-B65+F7 -> 12606.38
A42: Parte Irma | C42: Cássia
B65: =SUM(B43:B64) -> 0

Sheet Agosto 23
D2: 45139
B3: Vendas | C3: Gastos
A4: 1 | B4: 392 | C4: 42.07 | D4: Sacolas | E4: Dinheiro
A5: 2 | B5: 219 | C5: 1770.06 | D5: Cartao NU | E5: Pix
A6: 3 | B6: 212 | C6: 13 | E6: Cartao
A7: 4 | B7: 456 | C7: 88.34 | D7: Luz | F7: =SUM(F4:F6) -> 0
A8: 5 | B8: 1048
A9: 6 | B9: 279 | C9: 172 | D9: Leite
A10: 7 | B10: 110
A11: 8 | B11: 236
A12: 9 | B12: 192
A13: 10 | B13: 365
A14: 11 | B14: 397
A15: 12 | B15: 568
A16: 13 | B16: 84
A17: 14 | B17: 282
A18: 15 | B18: 269
A19: 16 | B19: 219
A20: 17 | B20: 263
A21: 18 | B21: 104
... A34: 31 | B34: 377
A35: Total | B35: =SUM(B4:B34) -> 9739 | C35: =SUM(C4:C34) -> 2085.47
A36: Total neto | B36: =B35-C35-B65+F7 -> 7653.53
A42: Parte Irma | C42: Cássia
B65: =SUM(B43:B64) -> 0

Sheet Julho 23
D2: 45108
B3: Vendas | C3: Gastos
A4: 1 | B4: 409 | C4: 0 | D4: Shopping s | E4: Dinheiro | F4: 212
A5: 2 | B5: 344 | C5: 957.16 | D5: Cartão N | E5: Pix | F5: 86
A6: 3 | B6: 194 | D6: Diesel | E6: Cartao | F6: 195
A7: 4 | B7: 79 | D7: Luz | F7: =SUM(F4:F6) -> 493
A8: 5 | B8: 43 | C8: 132.83 | D8: Leite
A9: 6 | B9: 215 | C9: 17.35
A10: 7 | B10: 145
A11: 8 | B11: 57
A12: 9 | B12: 513 | C12: 50 | D12: Freezer
A13: 10 | B13: 193
A14: 11 | B14: 185
A15: 12 | B15: 276
A16: 13 | B16: 116
A17: 14 | B17: 325
A18: 15 | B18: 356
A19: 16 | B19: 400
A20: 17 | B20: 52
A21: 18 | B21: 337
A22: 19 | B22: 258
A23: 20 | B23: 220
A24: 21 | B24: 251
... A34: 31 | B34: 187
A35: Total | B35: =SUM(B4:B34) -> 7999 | C35: =SUM(C4:C34) -> 1157.34
A36: Total neto | B36: =B35-C35-B65 -> 6741.66
A42: Parte Irma | C42: Cássia
B43: 100
B65: =SUM(B43:B64) -> 100

Sheet Junho 23
D2: 45078
B3: Vendas | C3: Gastos
A4: 1 | B4: 120 | C4: 407.4 | D4: Shopping s | E4: Dinheiro
A5: 2 | B5: 115 | C5: 1129.02 | D5: Cartão N | E5: Pix | F5: 50
A6: 3 | B6: 555 | D6: Diesel | E6: Cartao | F6: 30
A7: 4 | B7: 324 | D7: Luz | F7: =SUM(F4:F6) -> 80
A8: 5 | B8: 194 | C8: 70
A9: 6 | B9: 270
A10: 7 | B10: 304
A11: 8 | B11: 525
A12: 9 | B12: 398
A13: 10 | B13: 627
A14: 11 | B14: 0
A15: 12 | B15: 0
A16: 13 | B16: 0
A17: 14 | B17: 0
A18: 15 | B18: 0
A19: 16 | B19: 141
A20: 17 | B20: 441
... A34: 31 | B34: 0
A35: Total | B35: =SUM(B4:B34) -> 6134 | C35: =SUM(C4:C34) -> 1606.42
A36: Total neto | B36: =B35-C35-B65 -> 4527.58
A42: Parte Irma | C42: Cássia
B65: =SUM(B43:B64) -> 0

Sheet Maio 23
D3: 45047
B4: Vendas | C4: Gastos
A5: 1 | B5: 0 | C5: 488.2 | D5: Shopping s | E5: Dinheiro | F5: 41
A6: 2 | B6: 183 | C6: 1085.2 | D6: Cartão N | E6: Pix
A7: 3 | B7: 0 | D7: Diesel | E7: Cartao | F7: 58
A8: 4 | B8: 244 | C8: 81.55 | D8: Luz | F8: =SUM(F5:F7) -> 99
A9: 5 | B9: 388 | C9: 44.83
A10: 6 | B10: 1200
A11: 7 | B11: 666
A12: 8 | B12: 223
A13: 9 | B13: 230
A14: 10 | B14: 209
A15: 11 | B15: 141
A16: 12 | B16: 184
A17: 13 | B17: 829
A18: 14 | B18: 177
A19: 15 | B19: 234
A20: 16 | B20: 186
A21: 17 | B21: 155
... A34: 31 | B34: 108
A36: Total | B36: =SUM(B5:B35) -> 7534 | C36: =SUM(C5:C35) -> 1699.78
A37: Total neto | B37: =B36-C36-B66 -> 5834.22
A43: Parte Irma | C43: Cássia
B66: =SUM(B44:B65) -> 0

Sheet Abril 23
D3: 45017 | H3: Saldo Lucas gastos
B4: Vendas | C4: Gastos
A5: 1 | B5: 735 | C5: 603 | D5: Shopping s | E5: Dinheiro | F5: 378
A6: 2(2) | B6: 535 | C6: 1000 | D6: Cartão N | E6: Pix | F6: 64.5
A7: 3 | B7: 411 | C7: 428 | D7: Cartão A | E7: Cartao | F7: 93
A8: 4 | B8: 126 | C8: 49 | D8: Recheio | F8: =SUM(F5:F7) -> 535.5
A9: 5 | B9: 198
A10: 6 | B10: 0 | D10: Diesel
A11: 7 | B11: 787
A12: 8 | B12: 953
A13: 9(2) | B13: 271
A14: 10 | B14: 359
A15: 11 | B15: 377
A16: 12 | B16: 195
A17: 13 | B17: 200
A18: 14 | B18: 149
A19: 15 | B19: 552
A20: 16(2) | B20: 408
A21: 17 | B21: 75 | E21: Dinheiro | F21: Pix | G21: Cartao
A22: 18 | B22: 269 | E22: 3035
A23: 19 | B23: 166
A24: 20 | B24: 210
A25: 21 | B25: 357
A26: 22 | B26: 392
A27: 23 | B27: 490
A28: 24 | B28: 400
A29: 25 | B29: 129
A30: 26 | B30: 207
A31: 27 | B31: 158
A32: 28 | B32: 145
A33: 29 | B33: 535
A34: 30 | B34: 0
A36: Total | B36: =SUM(B5:B35) -> 9789 | C36: =SUM(C5:C35) -> 2080
A37: Total neto | B37: =B36-C36-B66 -> 6479
B38: 6420 | H38: =SUM(H4:H37) -> 0
H40: ='Novembro 22'!D19+B38 -> 6420
A43: Parte Irma | C43: Cássia
B44: 485 | C44: 267
B45: 437
B46: 308
...

Sheet Março 23
D3: Março 23 | H3: Saldo Lucas gastos
B4: Vendas | C4: Gastos
A5: 1 | B5: 379 | C5: 926.55 | D5: Shopping s | E5: Dinheiro | F5: 205
A6: 2 | B6: 285 | C6: 688.35 | D6: Cartão N | E6: Pix | F6: 72
A7: 3 | B7: 265 | C7: 370.58 | D7: Cartão A | E7: Cartao | F7: 139
A8: 4 | B8: 1040 | C8: 86 | D8: Luz | F8: =SUM(F5:F7) -> 416
A9: 5(2) | B9: 788 | C9: 10 | D9: Laine
A10: 6 | B10: 511 | C10: 84
A11: 7 | B11: 512
A12: 8 | B12: 428 | C12: 1 | D12: Diesel
A13: 9 | B13: 4
A14: 10 | B14: 421 | C14: 335.88
A15: 11 | B15: 561
A16: 12 | B16: 681
A17: 13 | B17: 172
A18: 14 | B18: 185
A19: 15 | B19: 442
A20: 16 | B20: 332
A21: 17 | B21: 401 | E21: Dinheiro | F21: Pix | G21: Cartao
A22: 18 | B22: 1041
A23: 19(2) | B23: 37
A24: 20 | B24: 277
A25: 21 | B25: 288
A26: 22 | B26: 310
A27: 23 | B27: 267
A28: 24 | B28: 268
A29: 25 | B29: 709
A30: 26(2) | B30: 619
A31: 27 | B31: 431
A32: 28 | B32: 431
A33: 29 | B33: 71
A34: 30(2) | B34: 308
A35: 31 | B35: 416
A36: Total | B36: =SUM(B5:B35) -> 12880 | C36: =SUM(C5:C35) -> 2502.36
A37: Total neto | B37: =B36-C36-B66 -> 8375.64
H38: =SUM(H4:H37) -> 0
H40: ='Novembro 22'!D19+B38 -> 0
A43: Parte Irma | C43: Cássia
B44: 788 | C44: 354
B45: 340
...

Sheet Fevereiro 23
D3: Fevereiro 23 | H3: Saldo Lucas gastos
B4: Vendas | C4: Gastos
A5: 1 | B5: 467 | C5: 23 | E5: Dinheiro | G5: Falta passar p conta inter
A6: 2 | B6: 312 | C6: 100 | E6: Pix | F6: 0 | G6: 3110
A7: 3 | B7: 178 | C7: 283 | E7: Cartao
A8: 4 | B8: 1196 | C8: 75 | D8: Luz | F8: =SUM(F5:F7) -> 0
A9: 5(2) | B9: 1119
A10: 6 | B10: 781
A11: 7 | B11: 0
A12: 8 | B12: 701
A13: 9 | B13: 639
A14: 10 | B14: 105
A15: 11 | B15: 546
A16: 12(2) | B16: 810
A17: 13 | B17: 330
A18: 14 | B18: 20
A19: 15 | B19: 386
A20: 16 | B20: 185
A21: 17 | B21: 262 | E21: Dinheiro | F21: Pix | G21: Cartao
A22: 18 | B22: 712
A23: 19(2) | B23: 364
A24: 20 | B24: 0
A25: 21 | B25: 462
A26: 22 | B26: 250
A27: 23 | B27: 5
A28: 24 | B28: 255
A29: 25 | B29: 688
A30: 26 | B30: 0
A31: 27 | B31: 237
A32: 28 | B32: 52
A36: Total | B36: =SUM(B5:B35) -> 11062 | C36: =SUM(C5:C35) -> 481
A37: Total neto | B37: =B36-C36-B66 -> 8502
H38: =SUM(H4:H37) -> 0
E40: Total neto a dia de hoje | H40: ='Novembro 22'!D19+B38 -> 0
A41: Vale alimentação | C41: 706.5
A43: Parte Irma | C43: Cássia
B44: 1119 | C44: 560
B45: 810 | C45: 405
B46: 150
B66: =SUM(B44:B65) -> 2079 | C66: =SUM(C44:C63) -> 965

Sheet Janeiro 23
D3: Janeiro 2023 | H3: Saldo Lucas gastos
B4: Vendas | C4: Gastos
A5: 1 | B5: 0 | C5: 8 | D5: Óleo | E5: Dinheiro
A6: 2 | B6: 942 | C6: 145 | D6: Pneu | E6: Pix
A7: 3 | B7: 540 | C7: 75 | D7: Luz | E7: Cartao
A8: 4 | B8: 560 | C8: 547.72 | D8: Atacadao+ Maxi | F8: =SUM(F5:F7) -> 0
A9: 5 | B9: 700 | C9: 183 | D9: Stock (Acucar+L)
A10: 6 | B10: 812 | C10: 181.92
A11: 7(2) | B11: 1227 | C11: 157.9
A12: 8(2) | B12: 887 | C12: 38
A13: 9 | B13: 616 | C13: 311.47
A14: 10 | B14: 504 | C14: 18
A15: 11 | B15: 887 | C15: 315
A16: 12 | B16: 319 | C16: 28.13 | D16: D Aparecida
A17: 13 | B17: 44 | C17: 23
A18: 14 | B18: 542 | C18: 53.88
A19: 15(2) | B19: 486 | C19: 415.86
A20: 16 | B20: 570 | C20: 191.5
A21: 17 | B21: 268 | E21: Dinheiro | F21: Pix | G21: Cartao
A22: 18 | B22: 408
A23: 19 | B23: 549 | C23: 100 | D23: Diesel
A24: 20 | B24: 708
A25: 21(2) | B25: 723
A26: 22(2) | B26: 870
A27: 23 | B27: 703
A28: 24 | B28: 376
A29: 25 | B29: 512
A30: 26 | B30: 482
A31: 27 | B31: 573
A32: 28 | B32: 900
A33: 29(2) | B33: 427
A34: 30 | B34: 160
A35: 31 | B35: 60
A36: Total | B36: =SUM(B5:B35) -> 17355 | C36: =SUM(C5:C35) -> 2793.38
A37: Total neto | B37: =B36-C36-B66 -> 11076.62
H38: =SUM(H4:H37) -> 0
E40: Total neto a dia de hoje | H40: ='Novembro 22'!D19+B38 -> 0
A41: Vale alimentação | C41: 600
A43: Parte Irma | C43: Cássia
A44: 7 | B44: 614
...

Sheet Dezembro 22
D2: Dezembro 2022 | G2: Saldo Lucas gastos
B3: Vendas | C3: Gastos | G3: 97.41
A4: 1 | B4: 566 | C4: 348 | D4: 7cx leite | G4: 78.64
A5: 2 | B5: 0 | C5: 7.3 | D5: 50tp 500ml | G5: -57.51
A6: 3 | B6: 1140 | C6: 194.82 | D6: Atacadao | G6: 19.68 | I6: Dinheiro
A7: 4 | B7: 737 | C7: 264.5 | D7: Stock agua | G7: 11.76 | I7: 1369
A8: 5 | B8: 554 | C8: 115.02 | D8: Açucar | G8: 50.76
A9: 6 | B9: 670 | G9: 244.08
A10: 7 | B10: 957 | C10: 105 | D10: Diesel | G10: 250
A11: 8 | B11: 829 | G11: 61.74
A12: 9 | B12: 826 | C12: 488 | D12: 10cx lt | G12: 310.6
A13: 10 | B13: 1449 | C13: 123.5 | D13: Stock agua | G13: 155.74
A14: 11 | B14: 475 | C14: 621.2 | D14: S sorveteiro | G14: 98
A15: 12 | B15: 430 | C15: 311.48 | D15: S sorveteiro | G15: -212.45
A16: 13 | B16: 542 | C16: 196.8 | D16: Leite | G16: 43.86
A17: 14 | B17: 569 | C17: 424.9
A18: 15 | B18: 388 | C18: 87.72
A19: 16 | B19: 729
A20: 17 | B20: 814
A21: 18 | B21: 990
A22: 19 | B22: 654
A23: 20 | B23: 860
A24: 21 | B24: 757
A25: 22 | B25: 758
A26: 23 | B26: 1121
A27: 24 | B27: 1317
A28: 25 | B28: 0
A29: 26 | B29: 855
A30: 27 | B30: 734
... A33: 30 | B33: 796
A34: 31 | B34: 667 | C34: 2680
A35: Total | B35: =SUM(B4:B34) -> 22622 | C35: =SUM(C4:C34) -> 5968.24
A36: Total neto | B36: =B35-C35 -> 16653.76
G37: =SUM(G3:G36) -> 1152.31
E39: Total neto a dia de hoje | G39: ='Novembro 22'!D18+B37 -> 1512.835
A40: Vale alimentação

Sheet Novembro 22
C2: Novembro/22
A4: 21 | B4: 443.33
A5: 23 | B5: 324.6 | F5: 1950
A6: 24 | B6: 284.33 | E6: Gastos | F6: 928
A7: 25 | B7: 627 | F7: =SUM(F5:F6) -> 2878
A8: 26 | B8: 732
A9: 27 | B9: 465.5
A10: 28 | B10: 247
A11: 29 | B11: 427.68
A12: 30 | B12: 402.23 | C12: Minha parte
B13: =SUM(B3:B12) -> 3953.67 | C13: =(B13-B3)/2 -> 1976.835
H16: %%
B18: Neto | C18: =B13-F7 -> 1075.67 | D18: =C13-(F6/2) -> 1512.835
